2020-02-10 00:28:58,676 opmysql.py[line:45] ERROR (2003, "Can't connect to MySQL server on '1.1.1.1' (timed out)")
Traceback (most recent call last):
  File "/Library/Frameworks/Python.framework/Versions/3.8/lib/python3.8/site-packages/pymysql/connections.py", line 581, in connect
    sock = socket.create_connection(
  File "/Library/Frameworks/Python.framework/Versions/3.8/lib/python3.8/socket.py", line 807, in create_connection
    raise err
  File "/Library/Frameworks/Python.framework/Versions/3.8/lib/python3.8/socket.py", line 796, in create_connection
    sock.connect(sa)
socket.timeout: timed out

During handling of the above exception, another exception occurred:

Traceback (most recent call last):
  File "/Users/sudonglei/PycharmProjects/autotest_interface/common/opmysql.py", line 33, in __init__
    self.conn = pymysql.connect(host=host_db, user=user_db, passwd=passwd_db, db=name_db, port=port_db,
  File "/Library/Frameworks/Python.framework/Versions/3.8/lib/python3.8/site-packages/pymysql/__init__.py", line 94, in Connect
    return Connection(*args, **kwargs)
  File "/Library/Frameworks/Python.framework/Versions/3.8/lib/python3.8/site-packages/pymysql/connections.py", line 325, in __init__
    self.connect()
  File "/Library/Frameworks/Python.framework/Versions/3.8/lib/python3.8/site-packages/pymysql/connections.py", line 630, in connect
    raise exc
pymysql.err.OperationalError: (2003, "Can't connect to MySQL server on '1.1.1.1' (timed out)")
